<?xml version="1.0"?>
<sdf version='1.7'>
  <world name='default'>
   <light name='sun' type='directional'>
      <cast_shadows>1</cast_shadows>
      <pose frame="">0 0 10 0 -0 0 </pose>
       <diffuse>0.8 0.8 0.8 1</diffuse>
      <specular>0.1 0.1 0.1 1</specular>
      <attenuation>
        <range>1000</range>
        <constant>0.9</constant>
        <linear>0.01</linear>
        <quadratic>0.001</quadratic>
      </attenuation>
      <direction>-0.5 0.5 -1</direction>
    </light>
    <model name='ground_plane'>
      <static>1</static>
      <link name='link'>
        <collision name='collision'>
          <geometry>
            <plane>
              <normal>0 0 1</normal>
              <size>100 100</size>
            </plane>
          </geometry>
          <surface>
            <contact>
              <collide_bitmask>65535</collide_bitmask>
              <ode/>
            </contact>
            <friction>
              <ode>
                <mu>100</mu>
                <mu2>50</mu2>
              </ode>
              <torsional>
                <ode/>
              </torsional>
            </friction>
            <bounce/>
          </surface>
          <max_contacts>10</max_contacts>
        </collision>
        <visual name='visual'>
          <cast_shadows>0</cast_shadows>
          <geometry>
            <plane>
              <normal>0 0 1</normal>
              <size>100 100</size>
            </plane>
          </geometry>
          <material>
            <script>
              <uri>file://media/materials/scripts/gazebo.material</uri>
              <name>Gazebo/Grey</name>
            </script>
          </material>
        </visual>
        <self_collide>0</self_collide>
        <enable_wind>0</enable_wind>
        <kinematic>0</kinematic>
      </link>
    </model>
    <gravity>0 0 -9.8</gravity>
    <magnetic_field>6e-06 2.3e-05 -4.2e-05</magnetic_field>
    <atmosphere type='adiabatic'/>
    <physics type='ode'>
      <max_step_size>0.001</max_step_size>
      <real_time_factor>1</real_time_factor>
      <real_time_update_rate>1000</real_time_update_rate>
    </physics>
    <scene>
      <ambient>0.4 0.4 0.4 1</ambient>
      <background>0.7 0.7 0.7 1</background>
      <shadows>1</shadows>
    </scene>
    <wind/>
    <spherical_coordinates>
      <surface_model>EARTH_WGS84</surface_model>
      <latitude_deg>0</latitude_deg>
      <longitude_deg>0</longitude_deg>
      <elevation>0</elevation>
      <heading_deg>0</heading_deg>
    </spherical_coordinates>
    <state world_name='default'>
      <sim_time>110 198000000</sim_time>
      <real_time>110 374728988</real_time>
      <wall_time>1605963790 638078727</wall_time>
      <iterations>110198</iterations>
      <model name='ground_plane'>
        <pose>0 0 0 0 -0 0</pose>
        <scale>1 1 1</scale>
        <link name='link'>
          <pose>0 0 0 0 -0 0</pose>
          <velocity>0 0 0 0 -0 0</velocity>
          <acceleration>0 0 0 0 -0 0</acceleration>
          <wrench>0 0 0 0 -0 0</wrench>
        </link>
      </model>
    </state>
    <gui fullscreen='0'>
      <camera name='user_camera'>
        <pose>5 -5 2 0 0.275643 2.35619</pose>
        <view_controller>orbit</view_controller>
        <projection_type>perspective</projection_type>
      </camera>
    </gui>
    <model name="robot1">
   <pose frame="">0 0 0 0 0 0</pose>
   <self_collide>1</self_collide>
   <link name="base">
    <pose>0 0 0.1 0 0 0 </pose>
    <collision name="baseC">
     <pose>0 0 0 0 0 0 </pose>
     <geometry>
      <box>
       <size> 0.5 1 0.2</size>
      </box>
     </geometry>
    </collision>
    <visual name="baseV">
     <pose>0 0 0 0 0 0 </pose>
     <geometry>
      <box>
       <size> 0.5 1 0.2</size>
      </box>
     </geometry>
    </visual>   
   </link>
   <link name="eslabon1">
   <pose frame="">0 0 0.7 0 0 0</pose>
    <collision name="eslabon1C">
     <pose>0 0 0 0 0 0 </pose>
     <geometry>
      <box>
       <size> 0.05 0.05 1</size>
      </box>
     </geometry>
    </collision>
    <visual name="eslabon1V">
     <pose>0 0 0 0 0 0 </pose>
     <geometry>
      <box>
       <size> 0.05 0.05 1</size>
      </box>
     </geometry>
    </visual>   
   </link>
   <link name="eslabon2">
   <pose frame="">0 0 1.64 0 0 0</pose>
    <collision name="eslabon2C">
     <pose>0 0 0 0 0 0 </pose>
     <geometry>
      <box>
       <size> 0.05 0.05 1</size>
      </box>
     </geometry>
    </collision>
    <visual name="eslabon2V">
     <pose>0 0 0 0 0 0 </pose>
     <geometry>
      <box>
       <size> 0.05 0.05 1</size>
      </box>
     </geometry>
    </visual>   
   </link>
   <link name="eslabon3">
   <pose frame="">0.1 0 2.59 0 0 0</pose>
    <collision name="eslabon3C">
     <pose>0 0 0 0 0 0 </pose>
     <geometry>
      <box>
       <size> 0.05 0.05 1</size>
      </box>
     </geometry>
    </collision>
    <visual name="eslabon3V">
     <pose>0 0 0 0 0 0 </pose>
     <geometry>
      <box>
       <size> 0.05 0.05 1</size>
      </box>
     </geometry>
    </visual>   
   </link>
   
   
   <joint name="elabon1J" type="revolute">
    <pose frame="">0 0 -0.5 0 0 0</pose>
    <parent>base</parent>
    <child>eslabon1</child>
    <axis>
     <dynamics>
      <damping>1</damping>
      <friction>0</friction>
      <spring_reference>0</spring_reference>
      <spring_stiffness>0</spring_stiffness>
     </dynamics>
    <limit>
     <lower>3.14</lower>
     <upper>3.14</upper>
    </limit>
     <xyz>0 0 -1</xyz>
     <use_parent_model_frame>1</use_parent_model_frame>
    </axis>  
   </joint>
   
   
    <joint name="elabon2J" type="revolute">
    <pose frame="">0 0 -0.475 0 0 0</pose>
    <parent>eslabon1</parent>
    <child>eslabon2</child>
    <axis>
     <dynamics>
      <damping>1</damping>
      <friction>0</friction>
      <spring_reference>0</spring_reference>
      <spring_stiffness>0</spring_stiffness>
     </dynamics>
    <limit>
     <lower>0</lower>
     <upper>3.14</upper>
    </limit>
     <xyz>1 0 0</xyz>
     <use_parent_model_frame>1</use_parent_model_frame>
    </axis>  
   </joint>
   
   <joint name="elabon3J" type="revolute">
    <pose frame="">0 0 -0.475 0 0 0</pose>
    <parent>eslabon2</parent>
    <child>eslabon3</child>
    <axis>
     <dynamics>
      <damping>1</damping>
      <friction>0</friction>
      <spring_reference>0</spring_reference>
      <spring_stiffness>0</spring_stiffness>
     </dynamics>
    <limit>
     <lower>3.14</lower>
     <upper>3.14</upper>
    </limit>
     <xyz>1 0 0</xyz>
     <use_parent_model_frame>1</use_parent_model_frame>
    </axis>  
   </joint>
   
   <plugin name="robot1" filename="librobot1.so">
   </pligin>
  </model> 
  </world>
</sdf>

